Workbook
Name YES: 'EOR_Data Gathering'!$D$44
Name YES: #REF!

Sheet Sor_f
A1: Core sample | B1: Year | C1: % Sor Reduction (AS) = Sorw- Sorc / Sorw, % | D1: % Sor Reduction (AS,P) = Sorw- Sorp / Sorw, % | E1: % Sor Reduction (SP) = Sorw- Sorp / Sorw
A2: LB-1_2013 | B2: 2013 | C2: 20 | D2: 42 | E2: 0
A3: LB-2_2013 | B3: 2013 | C3: 42 | D3: 49 | E3: 0
A4: LB-3_2013 | B4: 2013 | C4: 26 | D4: 32 | E4: 0
A5: LB-4_2013 | B5: 2013 | C5: 30 | D5: 52 | E5: 0
A6: LN-1_2013 | B6: 2013 | C6: 29 | D6: 33 | E6: 0
A7: 1L_2003 | B7: 2003 | C7: 0 | D7: 3.6 | E7: 0
A8: 2L_2003 | B8: 2003 | C8: 0 | D8: 20.6 | E8: 0
A9: 3L_2003 | B9: 2003 | C9: 0 | D9: 0 | E9: 9.8
A10: 4L_2003 | B10: 2003 | C10: 0 | D10: 14.1 | E10: 0
A11: 1R_2003 | B11: 2003 | C11: 0.79365079 | D11: 0 | E11: 0
A12: 2R_2003 | B12: 2003 | C12: 19.187359 | D12: 0 | E12: 0
A13: 3R_2003 | B13: 2003 | C13: 0 | D13: 0 | E13: 5.7275542
... A20: 10R_2003 | B20: 2003 | C20: 24.390244 | D20: 0 | E20: 0

Sheet Coreflood Summary
A1: Year | B1: Type | C1: Core Floof Sample | D1: Alkali Type & Concentration | E1: Surfactant Type & Concentration | F1: Polymer Type & Concentration
A2: 2013 | B2: ASP | C2: LB-1_2013 | D2: 1 % NaOH | E2: 0.075% ORS6-72 | F2: 1000 ppm SuperPusher
A3: 2013 | B3: ASP | C3: LB-2_2013 | D3: 1 % Na2C03 | E3: 0.075% ORS6-72 | F3: 1000 ppm SuperPusher
A4: 2013 | B4: ASP | C4: LB-3_2013 | D4: 1 % NaOH | E4: 0.075% ORS6-72 | F4: 1000 ppm SuperPusher
A5: 2013 | B5: ASP | C5: LB-4_2013 | D5: 1 % Na2C03 | E5: 0.075% ORS6-72 | F5: 1000 ppm SuperPusher
A6: 2013 | B6: ASP | C6: LN-1_2013 | D6: 1 % NaOH | E6: 0.075% ORS6-72 | F6: 1000 ppm SuperPusher
A7: 2003 | B7: ASP | C7: 1L_2003 | D7: % NaOH | E7: ORS 6-49 | F7: Flopaam 3630ST
A8: 2003 | B8: ASP | C8: 2L_2003 | D8: % Na2C03 | E8: 6 -72 | F8: Flopaam 3430ST
A9: 2003 | B9: SP | C9: 3L_2003 | D9: NA | E9: 6 -79 | F9: HE 300
A10: 2003 | B10: ASP | C10: 4L_2003 | D10: NA | E10: 6 -72 | F10: AN125
A11: 2003 | B11: S | C11: 1R_2003 | D11: NA | E11: 0.1% 6-79 | F11: NA
A12: 2003 | B12: AS | C12: 2R_2003 | D12: 0.05% NaOH | E12: 0.05% 6-72 | F12: NA
A13: 2003 | B13: SP | C13: 3R_2003 | D13: NA | E13: 0.15% 6-79 | F13: 0.05% HE300
... A20: 2003 | B20: AS | C20: 10R_2003 | D20: 1 % NaOH | E20: 0.075% 6-72 | F20: NA

Sheet map
A1: Number | B1: Field | C1: Types of EOR | D1: Year | E1: Type of Study | F1: LATITUDE | G1: LONGITUDE
A2: 1 | B2: Angsi | C2: CEOR ASP | D2: 2003 | E2: R&D /Lab Reports | F2: 5.18444 | G2: 104.72278
A3: 2 | B3: Angsi | C3: CEOR AS | D3: 2007 | E3: Pilot Field Application | F3: 5.18444 | G3: 104.72278
A4: 3 | B4: Angsi | C4: CEOR AS | D4: 2011 | E4: FDP Study | F4: 5.18444 | G4: 104.72278
A5: 4 | B5: Angsi | C5: CEOR ASP | D5: 2013 | E5: R&D /Lab Reports | F5: 5.18444 | G5: 104.72278
A6: 5 | B6: Angsi | C6: CEOR ASP | D6: 2014 | E6: FDP Study | F6: 5.18444 | G6: 104.72278
A7: 6 | B7: Angsi | C7: CEOR ASP | D7: 2018 | E7: SITOS Report | F7: 5.18444 | G7: 104.72278
A8: 7 | B8: Angsi | C8: CEOR Polymer | D8: 2025 | E8: Presentation Pack | F8: 5.18444 | G8: 104.72278
A9: 8 | B9: Dulang | C9: WAG | D9: 2005 | E9: R&D Report | F9: 5.84364 | G9: 104.136
A10: 9 | B10: Dulang | C10: WAG | D10: 2014 | E10: R&D /Lab Reports | F10: 5.84364 | G10: 104.136
A11: 10 | B11: Dulang | C11: MEOR | D11: 2004 | E11: R&D Report | F11: 5.84364 | G11: 104.136
A12: 11 | B12: Dulang | C12: EWAG | D12: 2005 | E12: SITOS Report | F12: 5.84364 | G12: 104.136
A13: 12 | B13: Dulang | C13: CEOR S-Foam | D13: 2014 | E13: R&D Report | F13: 5.84364 | G13: 104.136
... A20: 19 | B20: Baronia | C20: CEOR S-Foam | D20: 2018 | E20: R&D /Lab Reports | F20: 4.7395 | G20: 113.7406
A21: 20 | B21: Betty | C21: WAG | D21: 2013 | E21: R&D Report | F21: 4.60881 | G21: 113.64317
A22: 21 | B22: Bokor | C22: MEOR | D22: 1998 | E22: R&D Report | F22: 4.55 | G22: 113.624
A23: 22 | B23: Bokor | C23: MEOR | D23: 2000 | E23: R&D /Lab Reports | F23: 4.55 | G23: 113.624
A24: 23 | B24: Bokor | C24: WAG | D24: 2012 | E24: R&D /Lab Reports | F24: 4.55 | G24: 113.624
A25: 24 | B25: Bokor | C25: EWAG | D25: 2015 | E25: R&D Report | F25: 4.55 | G25: 113.624
A26: 25 | B26: Guntong | C26: WAG | D26: 2014 | E26: R&D Report | F26: 5.643 | G26: 105.044
A27: 26 | B27: Guntong | C27: EWAG | D27: 2014 | E27: R&D Report | F27: 5.643 | G27: 105.044
A28: 27 | B28: Samarang | C28: GASWAG | D28: 2012 | E28: R&D Report | F28: 5.618 | G28: 114.89
A29: 28 | B29: Samarang | C29: EWAG | D29: 2014 | E29: R&D Report | F29: 5.618 | G29: 114.89
A30: 29 | B30: South Furious 30 | C30: CEOR ASP | D30: 2016 | E30: R&D Report | F30: 6.78055 | G30: 116.20833
A31: 30 | B31: Barton | C31: CEOR ASP | D31: 2016 | E31: R&D Report | F31: 6.83333 | G31: 116.33333
A32: 31 | B32: South Furious 30 | C32: CEOR ASP | D32: 2017 | E32: R&D Report | F32: 6.78055 | G32: 116.20833
A33: 32 | B33: St Joseph | C33: CEOR ASP | D33: 2014 | E33: R&D /Lab Reports | F33: 6.63333 | G33: 116.1375
... A39: 38 | B39: West Lutong | C39: EWAG | D39: 2014 | E39: R&D Report | F39: 4.4825 | G39: 113.9961

Sheet Adsorption
A1: Sample No | B1: Year | C1: Field | D1: Surfactant | E1: Days | F1: Adsorption c/cO
A2: 1 | B2: 2003 | C2: Angsi | D2: SS-7064_( no alkali)_2003 | E2: -1 | F2: 1
A3: 1 | B3: 2003 | C3: Angsi | D3: SS-7064_( no alkali)_2003 | E3: 0 | F3: 0.19
A4: 1 | B4: 2003 | C4: Angsi | D4: SS-7064_( no alkali)_2003 | E4: 1 | F4: 0.19
A5: 1 | B5: 2003 | C5: Angsi | D5: SS-7064_( no alkali)_2003 | E5: 5 | F5: 0.18
A6: 1 | B6: 2003 | C6: Angsi | D6: SS-7064_( no alkali)_2003 | E6: 8 | F6: 0.17
A7: 1 | B7: 2003 | C7: Angsi | D7: SS-7064_( no alkali)_2003 | E7: 11 | F7: 0.16
A8: 1 | B8: 2003 | C8: Angsi | D8: SS-7064_( no alkali)_2003 | E8: 19 | F8: 0.15
A9: 2 | B9: 2003 | C9: Angsi | D9: Alcoflood 1235_(no alkali)_2003 | E9: -1 | F9: 1
A10: 2 | B10: 2003 | C10: Angsi | D10: Alcoflood 1235_(no alkali)_2003 | E10: 0 | F10: 0.9
A11: 2 | B11: 2003 | C11: Angsi | D11: Alcoflood 1235_(no alkali)_2003 | E11: 1 | F11: 0.8
A12: 2 | B12: 2003 | C12: Angsi | D12: Alcoflood 1235_(no alkali)_2003 | E12: 5 | F12: 0.58
A13: 2 | B13: 2003 | C13: Angsi | D13: Alcoflood 1235_(no alkali)_2003 | E13: 8 | F13: 0.38
... A33: 7 | B33: 2013 | C33: Angsi | D33: Formulation 43 (0.5 %M2 surfactant + S3B cosurfactant + 3.5 % NaCl)_2003 | E33: 14 | F33: 0.94

Sheet UserGuide
A1: EOR Screening Tool – User Guide
A3: 1. Fill in InputData column B. Dropdowns are provided for categorical criteria.
A4: 2. WAG-specific inputs are rows 33–38: water/gas facilities, WAG ratio, injectivity, and gravity override risk.
A5: 3. Screening sheet lists pass/fail, reasons, score, suitability, ΔRF, final RF, and EUR.
A6: 4. RF_EUR_Ranges shows P90/P50/P10 scenario ranges. Factors can be changed in ScenarioControls.
A7: 5. Criteria and References_2026 sheets provide traceability for thresholds and 2026 updates.
A8: 6. P10/P50/P90 values are screening-level estimates, not full probabilistic simulation outputs.
A9: 7. WAG was added as two separate methods: Miscible CO2 WAG and Immiscible Gas WAG.
A11: 7. CO2 vs HC gas and GOR logic:
A12: - CO2 and HC gas are now screened separately because MMP, source availability, corrosion/CCUS, and recycling logic differ.
A13: - Produced GOR is optional. If you do not have a numeric GOR, use Produced GOR Category instead.
A14: - If external HC gas is unavailable but Produced GOR is Moderate/High and Produced Gas Reinjectable = Yes, HC gas flood/WAG is treated as CONDITIONAL rather than automatic FAIL.
A15: - The numeric GOR helper uses screening defaults: >=1000 scf/STB = High, 300–999 = Moderate, <300 = Low. These are editable assumptions for early screening only.

Sheet InputData
A1: EOR Screening Tool 2026 – Input Data + Live Summary
A3: Parameter | B3: Value | C3: Unit / Notes | E3: Screening Summary (Live)
A4: Depth | C4: ft; True vertical depth of reservoir | E4: EOR Type | F4: Status | G4: Suitability | H4: Score (%) | I4: ΔRF_EOR (%) | J4: EUR P50 (MMstb)
A5: Reservoir Pressure | C5: psia | E5: =Screening!A2 -> CO2 Miscible Flood | F5: =Screening!E2 -> FAIL (critical) | G5: =Screening!F2 -> Not suitable | H5: =Screening!D2 -> 0 | I5: =Screening!G2 | J5: =RF_EUR_Ranges!I2
A6: Temperature | C6: °C | E6: =Screening!A3 -> CO2 WAG | F6: =Screening!E3 -> FAIL (critical) | G6: =Screening!F3 -> Not suitable | H6: =Screening!D3 -> 0 | I6: =Screening!G3 | J6: =RF_EUR_Ranges!I3
A7: Oil Viscosity | C7: cP | E7: =Screening!A4 -> HC Gas Miscible Flood | F7: =Screening!E4 -> FAIL (critical) | G7: =Screening!F4 -> Not suitable | H7: =Screening!D4 -> 0 | I7: =Screening!G4 | J7: =RF_EUR_Ranges!I4
A8: API Gravity | C8: °API | E8: =Screening!A5 -> HC Gas WAG | F8: =Screening!E5 -> FAIL (critical) | G8: =Screening!F5 -> Not suitable | H8: =Screening!D5 -> 0 | I8: =Screening!G5 | J8: =RF_EUR_Ranges!I5
A9: Permeability | C9: mD | E9: =Screening!A6 -> Immiscible Gas Flood | F9: =Screening!E6 -> FAIL (critical) | G9: =Screening!F6 -> Not suitable | H9: =Screening!D6 -> 0 | I9: =Screening!G6 | J9: =RF_EUR_Ranges!I6
A10: Porosity | C10: fraction; e.g. 0.25 | E10: =Screening!A7 -> Immiscible Gas WAG | F10: =Screening!E7 -> FAIL (critical) | G10: =Screening!F7 -> Not suitable | H10: =Screening!D7 -> 0 | I10: =Screening!G7 | J10: =RF_EUR_Ranges!I7
A11: Salinity (TDS) | C11: ppm | E11: =Screening!A8 -> Polymer (HPAM) | F11: =Screening!E8 -> FAIL (critical) | G11: =Screening!F8 -> Not suitable | H11: =Screening!D8 -> 0 | I11: =Screening!G8 | J11: =RF_EUR_Ranges!I8
A12: Hardness (Ca²⁺+Mg²⁺) | C12: ppm | E12: =Screening!A9 -> Polymer (ATBS) | F12: =Screening!E9 -> FAIL (critical) | G12: =Screening!F9 -> Not suitable | H12: =Screening!D9 -> 0 | I12: =Screening!G9 | J12: =RF_EUR_Ranges!I9
A13: Rock Type | C13: Sandstone / Carbonate | E13: =Screening!A10 -> SP | F13: =Screening!E10 -> FAIL (critical) | G13: =Screening!F10 -> Not suitable | H13: =Screening!D10 -> 0 | I13: =Screening!G10 | J13: =RF_EUR_Ranges!I10
A14: Net Pay | C14: m | E14: =Screening!A11 -> ASP | F14: =Screening!E11 -> FAIL (critical) | G14: =Screening!F11 -> Not suitable | H14: =Screening!D11 -> 0 | I14: =Screening!G11 | J14: =RF_EUR_Ranges!I11
A15: Heterogeneity | C15: Low / Moderate / High | E15: =Screening!A12 -> CSS | F15: =Screening!E12 -> FAIL (critical) | G15: =Screening!F12 -> Not suitable | H15: =Screening!D12 -> 0 | I15: =Screening!G12 | J15: =RF_EUR_Ranges!I12
A16: Gas Availability | C16: Yes / No; gas source for immiscible gas/WAG | E16: =Screening!A13 -> Steam Flood | F16: =Screening!E13 -> FAIL (critical) | G16: =Screening!F13 -> Not suitable | H16: =Screening!D13 -> 0 | I16: =Screening!G13 | J16: =RF_EUR_Ranges!I13
A17: Oxygen Present in Polymer System | C17: Yes / No | E17: =Screening!A14 -> ISC | F17: =Screening!E14 -> FAIL (critical) | G17: =Screening!F14 -> Not suitable | H17: =Screening!D14 -> 0 | I17: =Screening!G14 | J17: =RF_EUR_Ranges!I14
A18: OOIP | C18: MMstb; Original Oil In Place
A19: Base RF (without EOR) | C19: %; Current/expected RF before EOR | E19: Top Recommended EOR | F19: =Summary!B3 -> CO2 Miscible Flood
E20: Top Status | F20: =Summary!B5 -> FAIL (critical)
A21: Drive Mechanism | C21: Solution Gas / Water Drive / Gas Cap / Combination / Fractured / Others | E21: Top Suitability | F21: =Summary!B6 -> Not suitable
A22: Drive Mech Multiplier | C22: Calculated multiplier for ΔRF | E22: Top P50 EUR (MMstb) | F22: =Summary!B31
A23: CO2 Availability | C23: Yes / No; dedicated for miscible CO2/WAG screening
A24: MMP Satisfied? | C24: Yes / No; reservoir pressure at/above MMP
A25: Waterflood History | C25: Yes / No; successful waterflooding indicates residual oil/contact
A26: Water Cut | C26: %
A27: Field Maturity | C27: Early / Mid / Late
A28: Maturity Factor | C28: Calculated multiplier for ΔRF
A29: Mobility Ratio | C29: Favorable / Neutral / Unfavorable
A30: Surfactant Adsorption Risk | C30: Low / Medium / High
A31: Produced Water Handling Complexity | C31: Low / Medium / High
A32: Offshore Field? | C32: Yes / No
A33: Water Injection Facilities | C33: Yes / No; required for WAG
A34: Gas Injection Facilities | C34: Yes / No; required for WAG
... A44: GOR Category from Numeric | C44: Calculated helper from numeric GOR: >=1000 High, 300–999 Moderate, <300 Low

Sheet Screening
A1: EOR Type | B1: Critical Fail? | C1: Cause of Fail/Pass | D1: Score (%) | E1: Status | F1: Suitability | G1: ΔRF_EOR (%) | H1: Final RF (%) | I1: EUR (MMstb)
A2: CO2 Miscible Flood | B2: =OR(InputData!$B$8<25,InputData!$B$7>10,InputData!$B$4<2500,NOT(OR(InputData!$B$23="Yes",InputData!$B$23="YES",InputData!$B$23="yes")),NOT(OR(InputData!$B$24="Yes",InputData!$B$24="YES",InputData!$B$24="yes"))) -> TRUE | C2: =IF(InputData!$B$8<25,"API < 25°, ","")&IF(InputData!$B$7>10,"Viscosity > 10 cP, ","")&IF(InputData!$B$4<2500,"Depth < 2500 ft, ","")&IF(NOT(OR(InputData!$B$23="Yes",InputData!$B$23="YES",InputData!$B$23="yes")),"CO2 unavailable, ","")&IF(NOT(OR(InputData!$B$24="Yes",InputData!$B$24="YES",InputData!$B$24="yes")),"MMP not satisfied, ","") -> API < 25°, Depth < 2500 ft, CO2 unavailable, MMP not satisfied, | D2: =IF(B2,0,(IF(InputData!$B$8>=25,1,0)+IF(InputData!$B$7<=10,1,0)+IF(InputData!$B$4>=2500,1,0)+IF(OR(InputData!$B$23="Yes",InputData!$B$23="YES",InputData!$B$23="yes"),1,0)+IF(OR(InputData!$B$24="Yes",InputData!$B$24="YES",InputData!$B$24="yes"),1,0)+IF(OR(InputData!$B$25="Yes",InputData!$B$25="YES",InputData!$B$25="yes"),1,0)+IF(OR(InputData!$B$29="Favorable",InputData!$B$29="Neutral"),1,0))/7*100) -> 0 | E2: =IF(B2,"FAIL (critical)",IF(ISNUMBER(SEARCH("Conditional",C2)),"CONDITIONAL","PASS")) -> FAIL (critical) | F2: =IF(E2="FAIL (critical)","Not suitable",IF(E2="CONDITIONAL",IF(D2>=50,"Potentially suitable","Marginal"),IF(D2>=80,"Highly suitable",IF(D2>=50,"Potentially suitable","Marginal")))) -> Not suitable | G2: =IF(E2="FAIL (critical)","",D2/100*15*InputData!$B$22*InputData!$B$28) | H2: =IF(G2="","",InputData!$B$19+G2) | I2: =IF(H2="","",InputData!$B$18*H2/100)
A3: CO2 WAG | B3: =OR(InputData!$B$8<25,InputData!$B$7>10,NOT(OR(InputData!$B$23="Yes",InputData!$B$23="YES",InputData!$B$23="yes")),NOT(OR(InputData!$B$24="Yes",InputData!$B$24="YES",InputData!$B$24="yes")),NOT(OR(InputData!$B$33="Yes",InputData!$B$33="YES",InputData!$B$33="yes")),NOT(OR(InputData!$B$34="Yes",InputData!$B$34="YES",InputData!$B$34="yes"))) -> TRUE | C3: =IF(InputData!$B$8<25,"API < 25°, ","")&IF(InputData!$B$7>10,"Viscosity > 10 cP, ","")&IF(NOT(OR(InputData!$B$23="Yes",InputData!$B$23="YES",InputData!$B$23="yes")),"CO2 unavailable, ","")&IF(NOT(OR(InputData!$B$24="Yes",InputData!$B$24="YES",InputData!$B$24="yes")),"MMP not satisfied, ","")&IF(NOT(OR(InputData!$B$33="Yes",InputData!$B$33="YES",InputData!$B$33="yes")),"Water injection facilities unavailable, ","")&IF(NOT(OR(InputData!$B$34="Yes",InputData!$B$34="YES",InputData!$B$34="yes")),"Gas injection facilities unavailable, ","")&IF(InputData!$B$38="High","Conditional: gravity override risk high, ","") -> API < 25°, CO2 unavailable, MMP not satisfied, Water injection facilities unavailable, Gas injection facilities unavailable, | D3: =IF(B3,0,(IF(InputData!$B$8>=25,1,0)+IF(InputData!$B$7<=10,1,0)+IF(OR(InputData!$B$23="Yes",InputData!$B$23="YES",InputData!$B$23="yes"),1,0)+IF(OR(InputData!$B$24="Yes",InputData!$B$24="YES",InputData!$B$24="yes"),1,0)+IF(OR(InputData!$B$33="Yes",InputData!$B$33="YES",InputData!$B$33="yes"),1,0)+IF(OR(InputData!$B$34="Yes",InputData!$B$34="YES",InputData!$B$34="yes"),1,0)+IF(OR(InputData!$B$25="Yes",InputData!$B$25="YES",InputData!$B$25="yes"),1,0)+IF(OR(InputData!$B$36="Good",InputData!$B$36="Fair"),1,0)+IF(OR(InputData!$B$37="Good",InputData!$B$37="Fair"),1,0)+IF(OR(InputData!$B$38="Low",InputData!$B$38="Medium"),1,0))/10*100) -> 0 | E3: =IF(B3,"FAIL (critical)",IF(ISNUMBER(SEARCH("Conditional",C3)),"CONDITIONAL","PASS")) -> FAIL (critical) | F3: =IF(E3="FAIL (critical)","Not suitable",IF(E3="CONDITIONAL",IF(D3>=50,"Potentially suitable","Marginal"),IF(D3>=80,"Highly suitable",IF(D3>=50,"Potentially suitable","Marginal")))) -> Not suitable | G3: =IF(E3="FAIL (critical)","",D3/100*18*InputData!$B$22*InputData!$B$28) | H3: =IF(G3="","",InputData!$B$19+G3) | I3: =IF(H3="","",InputData!$B$18*H3/100)
A4: HC Gas Miscible Flood | B4: =OR(InputData!$B$8<25,InputData!$B$7>10,InputData!$B$4<2500,NOT(OR(InputData!$B$24="Yes",InputData!$B$24="YES",InputData!$B$24="yes")),NOT(OR(InputData!$B$42="Available/Conditional",InputData!$B$42="Available",InputData!$B$39="Yes",InputData!$B$39="YES",InputData!$B$39="yes"))) -> TRUE | C4: =IF(InputData!$B$8<25,"API < 25°, ","")&IF(InputData!$B$7>10,"Viscosity > 10 cP, ","")&IF(InputData!$B$4<2500,"Depth < 2500 ft, ","")&IF(NOT(OR(InputData!$B$24="Yes",InputData!$B$24="YES",InputData!$B$24="yes")),"MMP not satisfied, ","")&IF(NOT(OR(InputData!$B$42="Available/Conditional",InputData!$B$42="Available",InputData!$B$39="Yes",InputData!$B$39="YES",InputData!$B$39="yes")),"HC gas source unavailable, ","")&IF(AND(NOT(OR(InputData!$B$39="Yes",InputData!$B$39="YES",InputData!$B$39="yes")),OR(InputData!$B$40="High",InputData!$B$40="Moderate",InputData!$B$44="High",InputData!$B$44="Moderate"),OR(InputData!$B$41="Yes",InputData!$B$41="YES",InputData!$B$41="yes")),"Conditional: produced GOR supports HC gas reinjection/recycling, ","") -> API < 25°, Depth < 2500 ft, MMP not satisfied, HC gas source unavailable, | D4: =IF(B4,0,(IF(InputData!$B$8>=25,1,0)+IF(InputData!$B$7<=10,1,0)+IF(InputData!$B$4>=2500,1,0)+IF(OR(InputData!$B$24="Yes",InputData!$B$24="YES",InputData!$B$24="yes"),1,0)+IF(OR(InputData!$B$42="Available/Conditional",InputData!$B$42="Available",InputData!$B$39="Yes",InputData!$B$39="YES",InputData!$B$39="yes"),1,0)+IF(OR(InputData!$B$25="Yes",InputData!$B$25="YES",InputData!$B$25="yes"),1,0)+IF(OR(InputData!$B$29="Favorable",InputData!$B$29="Neutral"),1,0)+IF(OR(InputData!$B$40="High",InputData!$B$44="High"),1,IF(OR(InputData!$B$40="Moderate",InputData!$B$44="Moderate"),0.5,0)))/8*100) -> 0 | E4: =IF(B4,"FAIL (critical)",IF(ISNUMBER(SEARCH("Conditional",C4)),"CONDITIONAL","PASS")) -> FAIL (critical) | F4: =IF(E4="FAIL (critical)","Not suitable",IF(E4="CONDITIONAL",IF(D4>=50,"Potentially suitable","Marginal"),IF(D4>=80,"Highly suitable",IF(D4>=50,"Potentially suitable","Marginal")))) -> Not suitable | G4: =IF(E4="FAIL (critical)","",D4/100*14*InputData!$B$22*InputData!$B$28) | H4: =IF(G4="","",InputData!$B$19+G4) | I4: =IF(H4="","",InputData!$B$18*H4/100)
A5: HC Gas WAG | B5: =OR(InputData!$B$8<25,InputData!$B$7>10,NOT(OR(InputData!$B$24="Yes",InputData!$B$24="YES",InputData!$B$24="yes")),NOT(OR(InputData!$B$42="Available/Conditional",InputData!$B$42="Available",InputData!$B$39="Yes",InputData!$B$39="YES",InputData!$B$39="yes")),NOT(OR(InputData!$B$33="Yes",InputData!$B$33="YES",InputData!$B$33="yes")),NOT(OR(InputData!$B$34="Yes",InputData!$B$34="YES",InputData!$B$34="yes"))) -> TRUE | C5: =IF(InputData!$B$8<25,"API < 25°, ","")&IF(InputData!$B$7>10,"Viscosity > 10 cP, ","")&IF(NOT(OR(InputData!$B$24="Yes",InputData!$B$24="YES",InputData!$B$24="yes")),"MMP not satisfied, ","")&IF(NOT(OR(InputData!$B$42="Available/Conditional",InputData!$B$42="Available",InputData!$B$39="Yes",InputData!$B$39="YES",InputData!$B$39="yes")),"HC gas source unavailable, ","")&IF(NOT(OR(InputData!$B$33="Yes",InputData!$B$33="YES",InputData!$B$33="yes")),"Water injection facilities unavailable, ","")&IF(NOT(OR(InputData!$B$34="Yes",InputData!$B$34="YES",InputData!$B$34="yes")),"Gas injection facilities unavailable, ","")&IF(AND(NOT(OR(InputData!$B$39="Yes",InputData!$B$39="YES",InputData!$B$39="yes")),OR(InputData!$B$40="High",InputData!$B$40="Moderate",InputData!$B$44="High",InputData!$B$44="Moderate"),OR(InputData!$B$41="Yes",InputData!$B$41="YES",InputData!$B$41="yes")),"Conditional: produced GOR supports HC gas reinjection/recycling, ","")&IF(InputData!$B$38="High","Conditional: gravity override risk high, ","") -> API < 25°, MMP not satisfied, HC gas source unavailable, Water injection facilities unavailable, Gas injection facilities unavailable, | D5: =IF(B5,0,(IF(InputData!$B$8>=25,1,0)+IF(InputData!$B$7<=10,1,0)+IF(OR(InputData!$B$24="Yes",InputData!$B$24="YES",InputData!$B$24="yes"),1,0)+IF(OR(InputData!$B$42="Available/Conditional",InputData!$B$42="Available",InputData!$B$39="Yes",InputData!$B$39="YES",InputData!$B$39="yes"),1,0)+IF(OR(InputData!$B$33="Yes",InputData!$B$33="YES",InputData!$B$33="yes"),1,0)+IF(OR(InputData!$B$34="Yes",InputData!$B$34="YES",InputData!$B$34="yes"),1,0)+IF(OR(InputData!$B$25="Yes",InputData!$B$25="YES",InputData!$B$25="yes"),1,0)+IF(OR(InputData!$B$36="Good",InputData!$B$36="Fair"),1,0)+IF(OR(InputData!$B$37="Good",InputData!$B$37="Fair"),1,0)+IF(OR(InputData!$B$38="Low",InputData!$B$38="Medium"),1,0)+IF(OR(InputData!$B$40="High",InputData!$B$44="High"),1,IF(OR(InputData!$B$40="Moderate",InputData!$B$44="Moderate"),0.5,0)))/11*100) -> 0 | E5: =IF(B5,"FAIL (critical)",IF(ISNUMBER(SEARCH("Conditional",C5)),"CONDITIONAL","PASS")) -> FAIL (critical) | F5: =IF(E5="FAIL (critical)","Not suitable",IF(E5="CONDITIONAL",IF(D5>=50,"Potentially suitable","Marginal"),IF(D5>=80,"Highly suitable",IF(D5>=50,"Potentially suitable","Marginal")))) -> Not suitable | G5: =IF(E5="FAIL (critical)","",D5/100*17*InputData!$B$22*InputData!$B$28) | H5: =IF(G5="","",InputData!$B$19+G5) | I5: =IF(H5="","",InputData!$B$18*H5/100)
A6: Immiscible Gas Flood | B6: =OR(InputData!$B$8<15,InputData!$B$7>35,NOT(OR(OR(InputData!$B$16="Yes",InputData!$B$16="YES",InputData!$B$16="yes"),OR(InputData!$B$42="Available/Conditional",InputData!$B$42="Available",InputData!$B$39="Yes",InputData!$B$39="YES",InputData!$B$39="yes")))) -> TRUE | C6: =IF(InputData!$B$8<15,"API < 15°, ","")&IF(InputData!$B$7>35,"Viscosity > 35 cP, ","")&IF(NOT(OR(OR(InputData!$B$16="Yes",InputData!$B$16="YES",InputData!$B$16="yes"),OR(InputData!$B$42="Available/Conditional",InputData!$B$42="Available",InputData!$B$39="Yes",InputData!$B$39="YES",InputData!$B$39="yes"))),"Injection gas source unavailable, ","")&IF(AND(NOT(OR(InputData!$B$16="Yes",InputData!$B$16="YES",InputData!$B$16="yes")),AND(NOT(OR(InputData!$B$39="Yes",InputData!$B$39="YES",InputData!$B$39="yes")),OR(InputData!$B$40="High",InputData!$B$40="Moderate",InputData!$B$44="High",InputData!$B$44="Moderate"),OR(InputData!$B$41="Yes",InputData!$B$41="YES",InputData!$B$41="yes"))),"Conditional: produced GOR supports HC gas reinjection/recycling, ","") -> API < 15°, Injection gas source unavailable, | D6: =IF(B6,0,(IF(InputData!$B$8>=15,1,0)+IF(InputData!$B$7<=35,1,0)+IF(OR(OR(InputData!$B$16="Yes",InputData!$B$16="YES",InputData!$B$16="yes"),OR(InputData!$B$42="Available/Conditional",InputData!$B$42="Available",InputData!$B$39="Yes",InputData!$B$39="YES",InputData!$B$39="yes")),1,0)+IF(OR(InputData!$B$25="Yes",InputData!$B$25="YES",InputData!$B$25="yes"),1,0)+IF(OR(InputData!$B$29="Favorable",InputData!$B$29="Neutral"),1,0)+IF(OR(InputData!$B$40="High",InputData!$B$44="High"),1,IF(OR(InputData!$B$40="Moderate",InputData!$B$44="Moderate"),0.5,0)))/6*100) -> 0 | E6: =IF(B6,"FAIL (critical)",IF(ISNUMBER(SEARCH("Conditional",C6)),"CONDITIONAL","PASS")) -> FAIL (critical) | F6: =IF(E6="FAIL (critical)","Not suitable",IF(E6="CONDITIONAL",IF(D6>=50,"Potentially suitable","Marginal"),IF(D6>=80,"Highly suitable",IF(D6>=50,"Potentially suitable","Marginal")))) -> Not suitable | G6: =IF(E6="FAIL (critical)","",D6/100*8*InputData!$B$22*InputData!$B$28) | H6: =IF(G6="","",InputData!$B$19+G6) | I6: =IF(H6="","",InputData!$B$18*H6/100)
A7: Immiscible Gas WAG | B7: =OR(InputData!$B$8<15,InputData!$B$7>35,NOT(OR(OR(InputData!$B$16="Yes",InputData!$B$16="YES",InputData!$B$16="yes"),OR(InputData!$B$42="Available/Conditional",InputData!$B$42="Available",InputData!$B$39="Yes",InputData!$B$39="YES",InputData!$B$39="yes"))),NOT(OR(InputData!$B$33="Yes",InputData!$B$33="YES",InputData!$B$33="yes")),NOT(OR(InputData!$B$34="Yes",InputData!$B$34="YES",InputData!$B$34="yes"))) -> TRUE | C7: =IF(InputData!$B$8<15,"API < 15°, ","")&IF(InputData!$B$7>35,"Viscosity > 35 cP, ","")&IF(NOT(OR(OR(InputData!$B$16="Yes",InputData!$B$16="YES",InputData!$B$16="yes"),OR(InputData!$B$42="Available/Conditional",InputData!$B$42="Available",InputData!$B$39="Yes",InputData!$B$39="YES",InputData!$B$39="yes"))),"Injection gas source unavailable, ","")&IF(NOT(OR(InputData!$B$33="Yes",InputData!$B$33="YES",InputData!$B$33="yes")),"Water injection facilities unavailable, ","")&IF(NOT(OR(InputData!$B$34="Yes",InputData!$B$34="YES",InputData!$B$34="yes")),"Gas injection facilities unavailable, ","")&IF(AND(NOT(OR(InputData!$B$16="Yes",InputData!$B$16="YES",InputData!$B$16="yes")),AND(NOT(OR(InputData!$B$39="Yes",InputData!$B$39="YES",InputData!$B$39="yes")),OR(InputData!$B$40="High",InputData!$B$40="Moderate",InputData!$B$44="High",InputData!$B$44="Moderate"),OR(InputData!$B$41="Yes",InputData!$B$41="YES",InputData!$B$41="yes"))),"Conditional: produced GOR supports HC gas reinjection/recycling, ","")&IF(InputData!$B$38="High","Conditional: gravity override risk high, ","") -> API < 15°, Injection gas source unavailable, Water injection facilities unavailable, Gas injection facilities unavailable, | D7: =IF(B7,0,(IF(InputData!$B$8>=15,1,0)+IF(InputData!$B$7<=35,1,0)+IF(OR(OR(InputData!$B$16="Yes",InputData!$B$16="YES",InputData!$B$16="yes"),OR(InputData!$B$42="Available/Conditional",InputData!$B$42="Available",InputData!$B$39="Yes",InputData!$B$39="YES",InputData!$B$39="yes")),1,0)+IF(OR(InputData!$B$33="Yes",InputData!$B$33="YES",InputData!$B$33="yes"),1,0)+IF(OR(InputData!$B$34="Yes",InputData!$B$34="YES",InputData!$B$34="yes"),1,0)+IF(OR(InputData!$B$25="Yes",InputData!$B$25="YES",InputData!$B$25="yes"),1,0)+IF(OR(InputData!$B$36="Good",InputData!$B$36="Fair"),1,0)+IF(OR(InputData!$B$37="Good",InputData!$B$37="Fair"),1,0)+IF(OR(InputData!$B$38="Low",InputData!$B$38="Medium"),1,0)+IF(OR(InputData!$B$40="High",InputData!$B$44="High"),1,IF(OR(InputData!$B$40="Moderate",InputData!$B$44="Moderate"),0.5,0)))/10*100) -> 0 | E7: =IF(B7,"FAIL (critical)",IF(ISNUMBER(SEARCH("Conditional",C7)),"CONDITIONAL","PASS")) -> FAIL (critical) | F7: =IF(E7="FAIL (critical)","Not suitable",IF(E7="CONDITIONAL",IF(D7>=50,"Potentially suitable","Marginal"),IF(D7>=80,"Highly suitable",IF(D7>=50,"Potentially suitable","Marginal")))) -> Not suitable | G7: =IF(E7="FAIL (critical)","",D7/100*12*InputData!$B$22*InputData!$B$28) | H7: =IF(G7="","",InputData!$B$19+G7) | I7: =IF(H7="","",InputData!$B$18*H7/100)
A8: Polymer (HPAM) | B8: =OR(InputData!$B$6>70,InputData!$B$11>70000,InputData!$B$12>500,InputData!$B$9<50,OR(InputData!$B$17="Yes",InputData!$B$17="YES",InputData!$B$17="yes")) -> TRUE | C8: =IF(InputData!$B$6>70,"Temperature > 70°C, ","")&IF(InputData!$B$11>70000,"TDS > 70,000 ppm, ","")&IF(InputData!$B$12>500,"Hardness > 500 ppm, ","")&IF(InputData!$B$9<50,"Permeability < 50 mD, ","")&IF(OR(InputData!$B$17="Yes",InputData!$B$17="YES",InputData!$B$17="yes"),"Oxygen control required, ","") -> Permeability < 50 mD, | D8: =IF(B8,0,(IF(InputData!$B$6<=70,1,0)+IF(InputData!$B$11<=70000,1,0)+IF(InputData!$B$12<=500,1,0)+IF(InputData!$B$9>=50,1,0)+IF(NOT(OR(InputData!$B$17="Yes",InputData!$B$17="YES",InputData!$B$17="yes")),1,0)+IF(InputData!$B$26>=50,1,0)+IF(OR(InputData!$B$29="Favorable",InputData!$B$29="Neutral"),1,0))/7*100) -> 0 | E8: =IF(B8,"FAIL (critical)",IF(ISNUMBER(SEARCH("Conditional",C8)),"CONDITIONAL","PASS")) -> FAIL (critical) | F8: =IF(E8="FAIL (critical)","Not suitable",IF(E8="CONDITIONAL",IF(D8>=50,"Potentially suitable","Marginal"),IF(D8>=80,"Highly suitable",IF(D8>=50,"Potentially suitable","Marginal")))) -> Not suitable | G8: =IF(E8="FAIL (critical)","",D8/100*10*InputData!$B$22*InputData!$B$28) | H8: =IF(G8="","",InputData!$B$19+G8) | I8: =IF(H8="","",InputData!$B$18*H8/100)
A9: Polymer (ATBS) | B9: =OR(InputData!$B$6>120,InputData!$B$11>250000,InputData!$B$12>5000,InputData!$B$9<30,OR(InputData!$B$17="Yes",InputData!$B$17="YES",InputData!$B$17="yes")) -> TRUE | C9: =IF(InputData!$B$6>120,"Temperature > 120°C, ","")&IF(InputData!$B$11>250000,"TDS > 250,000 ppm, ","")&IF(InputData!$B$12>5000,"Hardness > 5,000 ppm, ","")&IF(InputData!$B$9<30,"Permeability < 30 mD, ","")&IF(OR(InputData!$B$17="Yes",InputData!$B$17="YES",InputData!$B$17="yes"),"Oxygen control required, ","") -> Permeability < 30 mD, | D9: =IF(B9,0,(IF(InputData!$B$6<=120,1,0)+IF(InputData!$B$11<=250000,1,0)+IF(InputData!$B$12<=5000,1,0)+IF(InputData!$B$9>=30,1,0)+IF(NOT(OR(InputData!$B$17="Yes",InputData!$B$17="YES",InputData!$B$17="yes")),1,0)+IF(InputData!$B$26>=50,1,0)+IF(OR(InputData!$B$29="Favorable",InputData!$B$29="Neutral"),1,0))/7*100) -> 0 | E9: =IF(B9,"FAIL (critical)",IF(ISNUMBER(SEARCH("Conditional",C9)),"CONDITIONAL","PASS")) -> FAIL (critical) | F9: =IF(E9="FAIL (critical)","Not suitable",IF(E9="CONDITIONAL",IF(D9>=50,"Potentially suitable","Marginal"),IF(D9>=80,"Highly suitable",IF(D9>=50,"Potentially suitable","Marginal")))) -> Not suitable | G9: =IF(E9="FAIL (critical)","",D9/100*12*InputData!$B$22*InputData!$B$28) | H9: =IF(G9="","",InputData!$B$19+G9) | I9: =IF(H9="","",InputData!$B$18*H9/100)
A10: SP | B10: =OR(InputData!$B$8<20,InputData!$B$7>35,InputData!$B$6>100,InputData!$B$11>100000,InputData!$B$30="High",InputData!$B$31="High") -> TRUE | C10: =IF(InputData!$B$8<20,"API < 20°, ","")&IF(InputData!$B$7>35,"Viscosity > 35 cP, ","")&IF(InputData!$B$6>100,"Temperature > 100°C, ","")&IF(InputData!$B$11>100000,"TDS > 100,000 ppm, ","")&IF(InputData!$B$30="High","Adsorption risk high, ","")&IF(InputData!$B$31="High","Produced-water handling high, ","") -> API < 20°, | D10: =IF(B10,0,(IF(InputData!$B$8>=20,1,0)+IF(InputData!$B$7<=35,1,0)+IF(InputData!$B$6<=100,1,0)+IF(InputData!$B$11<=100000,1,0)+IF(OR(InputData!$B$30="Low",InputData!$B$30="Medium"),1,0)+IF(OR(InputData!$B$31="Low",InputData!$B$31="Medium"),1,0)+IF(OR(InputData!$B$13="Sandstone",InputData!$B$13="Carbonate"),1,0)+IF(InputData!$B$26>=50,1,0))/8*100) -> 0 | E10: =IF(B10,"FAIL (critical)",IF(ISNUMBER(SEARCH("Conditional",C10)),"CONDITIONAL","PASS")) -> FAIL (critical) | F10: =IF(E10="FAIL (critical)","Not suitable",IF(E10="CONDITIONAL",IF(D10>=50,"Potentially suitable","Marginal"),IF(D10>=80,"Highly suitable",IF(D10>=50,"Potentially suitable","Marginal")))) -> Not suitable | G10: =IF(E10="FAIL (critical)","",D10/100*15*InputData!$B$22*InputData!$B$28) | H10: =IF(G10="","",InputData!$B$19+G10) | I10: =IF(H10="","",InputData!$B$18*H10/100)
A11: ASP | B11: =OR(InputData!$B$8<22,InputData!$B$7>30,InputData!$B$6>90,InputData!$B$11>10000,InputData!$B$12>50,NOT(OR(InputData!$B$13="Sandstone",InputData!$B$13="sandstone"))) -> TRUE | C11: =IF(InputData!$B$8<22,"API < 22°, ","")&IF(InputData!$B$7>30,"Viscosity > 30 cP, ","")&IF(InputData!$B$6>90,"Temperature > 90°C, ","")&IF(InputData!$B$11>10000,"TDS > 10,000 ppm, ","")&IF(InputData!$B$12>50,"Hardness > 50 ppm, ","")&IF(NOT(OR(InputData!$B$13="Sandstone",InputData!$B$13="sandstone")),"Requires sandstone, ","") -> API < 22°, Requires sandstone, | D11: =IF(B11,0,(IF(InputData!$B$8>=22,1,0)+IF(InputData!$B$7<=30,1,0)+IF(InputData!$B$6<=90,1,0)+IF(InputData!$B$11<=10000,1,0)+IF(InputData!$B$12<=50,1,0)+IF(OR(InputData!$B$13="Sandstone",InputData!$B$13="sandstone"),1,0)+IF(OR(InputData!$B$31="Low",InputData!$B$31="Medium"),1,0)+IF(InputData!$B$26>=50,1,0))/8*100) -> 0 | E11: =IF(B11,"FAIL (critical)",IF(ISNUMBER(SEARCH("Conditional",C11)),"CONDITIONAL","PASS")) -> FAIL (critical) | F11: =IF(E11="FAIL (critical)","Not suitable",IF(E11="CONDITIONAL",IF(D11>=50,"Potentially suitable","Marginal"),IF(D11>=80,"Highly suitable",IF(D11>=50,"Potentially suitable","Marginal")))) -> Not suitable | G11: =IF(E11="FAIL (critical)","",D11/100*20*InputData!$B$22*InputData!$B$28) | H11: =IF(G11="","",InputData!$B$19+G11) | I11: =IF(H11="","",InputData!$B$18*H11/100)
A12: CSS | B12: =OR(InputData!$B$7<100,InputData!$B$4>3000,InputData!$B$9<500) -> TRUE | C12: =IF(InputData!$B$7<100,"Viscosity < 100 cP, ","")&IF(InputData!$B$4>3000,"Depth > 3000 ft, ","")&IF(InputData!$B$9<500,"Permeability < 500 mD, ","") -> Viscosity < 100 cP, Permeability < 500 mD, | D12: =IF(B12,0,(IF(InputData!$B$7>=100,1,0)+IF(InputData!$B$4<=3000,1,0)+IF(InputData!$B$9>=500,1,0)+IF(OR(InputData!$B$32="No",InputData!$B$32="NO",InputData!$B$32="no"),1,0))/4*100) -> 0 | E12: =IF(B12,"FAIL (critical)",IF(ISNUMBER(SEARCH("Conditional",C12)),"CONDITIONAL","PASS")) -> FAIL (critical) | F12: =IF(E12="FAIL (critical)","Not suitable",IF(E12="CONDITIONAL",IF(D12>=50,"Potentially suitable","Marginal"),IF(D12>=80,"Highly suitable",IF(D12>=50,"Potentially suitable","Marginal")))) -> Not suitable | G12: =IF(E12="FAIL (critical)","",D12/100*15*InputData!$B$22*InputData!$B$28) | H12: =IF(G12="","",InputData!$B$19+G12) | I12: =IF(H12="","",InputData!$B$18*H12/100)
A13: Steam Flood | B13: =OR(InputData!$B$7<100,InputData!$B$4>3000,InputData!$B$9<1000) -> TRUE | C13: =IF(InputData!$B$7<100,"Viscosity < 100 cP, ","")&IF(InputData!$B$4>3000,"Depth > 3000 ft, ","")&IF(InputData!$B$9<1000,"Permeability < 1000 mD, ","") -> Viscosity < 100 cP, Permeability < 1000 mD, | D13: =IF(B13,0,(IF(InputData!$B$7>=100,1,0)+IF(InputData!$B$4<=3000,1,0)+IF(InputData!$B$9>=1000,1,0)+IF(OR(InputData!$B$32="No",InputData!$B$32="NO",InputData!$B$32="no"),1,0))/4*100) -> 0 | E13: =IF(B13,"FAIL (critical)",IF(ISNUMBER(SEARCH("Conditional",C13)),"CONDITIONAL","PASS")) -> FAIL (critical) | F13: =IF(E13="FAIL (critical)","Not suitable",IF(E13="CONDITIONAL",IF(D13>=50,"Potentially suitable","Marginal"),IF(D13>=80,"Highly suitable",IF(D13>=50,"Potentially suitable","Marginal")))) -> Not suitable | G13: =IF(E13="FAIL (critical)","",D13/100*18*InputData!$B$22*InputData!$B$28) | H13: =IF(G13="","",InputData!$B$19+G13) | I13: =IF(H13="","",InputData!$B$18*H13/100)
A14: ISC | B14: =OR(InputData!$B$7<10,InputData!$B$7>200,InputData!$B$9<200) -> TRUE | C14: =IF(InputData!$B$7<10,"Viscosity < 10 cP, ","")&IF(InputData!$B$7>200,"Viscosity > 200 cP, ","")&IF(InputData!$B$9<200,"Permeability < 200 mD, ","") -> Viscosity < 10 cP, Permeability < 200 mD, | D14: =IF(B14,0,(IF(AND(InputData!$B$7>=10,InputData!$B$7<=200),1,0)+IF(InputData!$B$9>=200,1,0)+IF(OR(InputData!$B$32="No",InputData!$B$32="NO",InputData!$B$32="no"),1,0))/3*100) -> 0 | E14: =IF(B14,"FAIL (critical)",IF(ISNUMBER(SEARCH("Conditional",C14)),"CONDITIONAL","PASS")) -> FAIL (critical) | F14: =IF(E14="FAIL (critical)","Not suitable",IF(E14="CONDITIONAL",IF(D14>=50,"Potentially suitable","Marginal"),IF(D14>=80,"Highly suitable",IF(D14>=50,"Potentially suitable","Marginal")))) -> Not suitable | G14: =IF(E14="FAIL (critical)","",D14/100*10*InputData!$B$22*InputData!$B$28) | H14: =IF(G14="","",InputData!$B$19+G14) | I14: =IF(H14="","",InputData!$B$18*H14/100)

Sheet Ranking
A1: Rank | B1: EOR Type | C1: Score (%) | D1: Status | E1: Suitability
A2: 1 | B2: =INDEX(Screening!$A$2:$A$14,MATCH(C2,Screening!$D$2:$D$14,0)) -> CO2 Miscible Flood | C2: =LARGE(Screening!$D$2:$D$14,A2) -> 0 | D2: =INDEX(Screening!$E$2:$E$14,MATCH(B2,Screening!$A$2:$A$14,0)) -> FAIL (critical) | E2: =INDEX(Screening!$F$2:$F$14,MATCH(B2,Screening!$A$2:$A$14,0)) -> Not suitable
A3: 2 | B3: =INDEX(Screening!$A$2:$A$14,MATCH(C3,Screening!$D$2:$D$14,0)) -> CO2 Miscible Flood | C3: =LARGE(Screening!$D$2:$D$14,A3) -> 0 | D3: =INDEX(Screening!$E$2:$E$14,MATCH(B3,Screening!$A$2:$A$14,0)) -> FAIL (critical) | E3: =INDEX(Screening!$F$2:$F$14,MATCH(B3,Screening!$A$2:$A$14,0)) -> Not suitable
A4: 3 | B4: =INDEX(Screening!$A$2:$A$14,MATCH(C4,Screening!$D$2:$D$14,0)) -> CO2 Miscible Flood | C4: =LARGE(Screening!$D$2:$D$14,A4) -> 0 | D4: =INDEX(Screening!$E$2:$E$14,MATCH(B4,Screening!$A$2:$A$14,0)) -> FAIL (critical) | E4: =INDEX(Screening!$F$2:$F$14,MATCH(B4,Screening!$A$2:$A$14,0)) -> Not suitable
A5: 4 | B5: =INDEX(Screening!$A$2:$A$14,MATCH(C5,Screening!$D$2:$D$14,0)) -> CO2 Miscible Flood | C5: =LARGE(Screening!$D$2:$D$14,A5) -> 0 | D5: =INDEX(Screening!$E$2:$E$14,MATCH(B5,Screening!$A$2:$A$14,0)) -> FAIL (critical) | E5: =INDEX(Screening!$F$2:$F$14,MATCH(B5,Screening!$A$2:$A$14,0)) -> Not suitable
A6: 5 | B6: =INDEX(Screening!$A$2:$A$14,MATCH(C6,Screening!$D$2:$D$14,0)) -> CO2 Miscible Flood | C6: =LARGE(Screening!$D$2:$D$14,A6) -> 0 | D6: =INDEX(Screening!$E$2:$E$14,MATCH(B6,Screening!$A$2:$A$14,0)) -> FAIL (critical) | E6: =INDEX(Screening!$F$2:$F$14,MATCH(B6,Screening!$A$2:$A$14,0)) -> Not suitable
A7: 6 | B7: =INDEX(Screening!$A$2:$A$14,MATCH(C7,Screening!$D$2:$D$14,0)) -> CO2 Miscible Flood | C7: =LARGE(Screening!$D$2:$D$14,A7) -> 0 | D7: =INDEX(Screening!$E$2:$E$14,MATCH(B7,Screening!$A$2:$A$14,0)) -> FAIL (critical) | E7: =INDEX(Screening!$F$2:$F$14,MATCH(B7,Screening!$A$2:$A$14,0)) -> Not suitable
A8: 7 | B8: =INDEX(Screening!$A$2:$A$14,MATCH(C8,Screening!$D$2:$D$14,0)) -> CO2 Miscible Flood | C8: =LARGE(Screening!$D$2:$D$14,A8) -> 0 | D8: =INDEX(Screening!$E$2:$E$14,MATCH(B8,Screening!$A$2:$A$14,0)) -> FAIL (critical) | E8: =INDEX(Screening!$F$2:$F$14,MATCH(B8,Screening!$A$2:$A$14,0)) -> Not suitable
A9: 8 | B9: =INDEX(Screening!$A$2:$A$14,MATCH(C9,Screening!$D$2:$D$14,0)) -> CO2 Miscible Flood | C9: =LARGE(Screening!$D$2:$D$14,A9) -> 0 | D9: =INDEX(Screening!$E$2:$E$14,MATCH(B9,Screening!$A$2:$A$14,0)) -> FAIL (critical) | E9: =INDEX(Screening!$F$2:$F$14,MATCH(B9,Screening!$A$2:$A$14,0)) -> Not suitable
A10: 9 | B10: =INDEX(Screening!$A$2:$A$14,MATCH(C10,Screening!$D$2:$D$14,0)) -> CO2 Miscible Flood | C10: =LARGE(Screening!$D$2:$D$14,A10) -> 0 | D10: =INDEX(Screening!$E$2:$E$14,MATCH(B10,Screening!$A$2:$A$14,0)) -> FAIL (critical) | E10: =INDEX(Screening!$F$2:$F$14,MATCH(B10,Screening!$A$2:$A$14,0)) -> Not suitable
A11: 10 | B11: =INDEX(Screening!$A$2:$A$14,MATCH(C11,Screening!$D$2:$D$14,0)) -> CO2 Miscible Flood | C11: =LARGE(Screening!$D$2:$D$14,A11) -> 0 | D11: =INDEX(Screening!$E$2:$E$14,MATCH(B11,Screening!$A$2:$A$14,0)) -> FAIL (critical) | E11: =INDEX(Screening!$F$2:$F$14,MATCH(B11,Screening!$A$2:$A$14,0)) -> Not suitable
A12: 11 | B12: =INDEX(Screening!$A$2:$A$14,MATCH(C12,Screening!$D$2:$D$14,0)) -> CO2 Miscible Flood | C12: =LARGE(Screening!$D$2:$D$14,A12) -> 0 | D12: =INDEX(Screening!$E$2:$E$14,MATCH(B12,Screening!$A$2:$A$14,0)) -> FAIL (critical) | E12: =INDEX(Screening!$F$2:$F$14,MATCH(B12,Screening!$A$2:$A$14,0)) -> Not suitable
A13: 12 | B13: =INDEX(Screening!$A$2:$A$14,MATCH(C13,Screening!$D$2:$D$14,0)) -> CO2 Miscible Flood | C13: =LARGE(Screening!$D$2:$D$14,A13) -> 0 | D13: =INDEX(Screening!$E$2:$E$14,MATCH(B13,Screening!$A$2:$A$14,0)) -> FAIL (critical) | E13: =INDEX(Screening!$F$2:$F$14,MATCH(B13,Screening!$A$2:$A$14,0)) -> Not suitable
A14: 13 | B14: =INDEX(Screening!$A$2:$A$14,MATCH(C14,Screening!$D$2:$D$14,0)) -> CO2 Miscible Flood | C14: =LARGE(Screening!$D$2:$D$14,A14) -> 0 | D14: =INDEX(Screening!$E$2:$E$14,MATCH(B14,Screening!$A$2:$A$14,0)) -> FAIL (critical) | E14: =INDEX(Screening!$F$2:$F$14,MATCH(B14,Screening!$A$2:$A$14,0)) -> Not suitable

Sheet RF_EUR_Ranges
A1: EOR Type | B1: Status | C1: Suitability | D1: ΔRF P90 (%) | E1: Final RF P90 (%) | F1: EUR P90 (MMstb) | G1: ΔRF P50 (%) | H1: Final RF P50 (%) | I1: EUR P50 (MMstb) | J1: ΔRF P10 (%) | K1: Final RF P10 (%) | L1: EUR P10 (MMstb)
A2: =Screening!A2 -> CO2 Miscible Flood | B2: =Screening!E2 -> FAIL (critical) | C2: =Screening!F2 -> Not suitable | D2: =IF(Screening!G2="","",Screening!G2*ScenarioControls!$B$3) | E2: =IF(D2="","",InputData!$B$19+D2) | F2: =IF(E2="","",InputData!$B$18*E2/100) | G2: =IF(Screening!G2="","",Screening!G2*ScenarioControls!$B$4) | H2: =IF(G2="","",InputData!$B$19+G2) | I2: =IF(H2="","",InputData!$B$18*H2/100) | J2: =IF(Screening!G2="","",Screening!G2*ScenarioControls!$B$5) | K2: =IF(J2="","",InputData!$B$19+J2) | L2: =IF(K2="","",InputData!$B$18*K2/100)
A3: =Screening!A3 -> CO2 WAG | B3: =Screening!E3 -> FAIL (critical) | C3: =Screening!F3 -> Not suitable | D3: =IF(Screening!G3="","",Screening!G3*ScenarioControls!$B$3) | E3: =IF(D3="","",InputData!$B$19+D3) | F3: =IF(E3="","",InputData!$B$18*E3/100) | G3: =IF(Screening!G3="","",Screening!G3*ScenarioControls!$B$4) | H3: =IF(G3="","",InputData!$B$19+G3) | I3: =IF(H3="","",InputData!$B$18*H3/100) | J3: =IF(Screening!G3="","",Screening!G3*ScenarioControls!$B$5) | K3: =IF(J3="","",InputData!$B$19+J3) | L3: =IF(K3="","",InputData!$B$18*K3/100)
A4: =Screening!A4 -> HC Gas Miscible Flood | B4: =Screening!E4 -> FAIL (critical) | C4: =Screening!F4 -> Not suitable | D4: =IF(Screening!G4="","",Screening!G4*ScenarioControls!$B$3) | E4: =IF(D4="","",InputData!$B$19+D4) | F4: =IF(E4="","",InputData!$B$18*E4/100) | G4: =IF(Screening!G4="","",Screening!G4*ScenarioControls!$B$4) | H4: =IF(G4="","",InputData!$B$19+G4) | I4: =IF(H4="","",InputData!$B$18*H4/100) | J4: =IF(Screening!G4="","",Screening!G4*ScenarioControls!$B$5) | K4: =IF(J4="","",InputData!$B$19+J4) | L4: =IF(K4="","",InputData!$B$18*K4/100)
A5: =Screening!A5 -> HC Gas WAG | B5: =Screening!E5 -> FAIL (critical) | C5: =Screening!F5 -> Not suitable | D5: =IF(Screening!G5="","",Screening!G5*ScenarioControls!$B$3) | E5: =IF(D5="","",InputData!$B$19+D5) | F5: =IF(E5="","",InputData!$B$18*E5/100) | G5: =IF(Screening!G5="","",Screening!G5*ScenarioControls!$B$4) | H5: =IF(G5="","",InputData!$B$19+G5) | I5: =IF(H5="","",InputData!$B$18*H5/100) | J5: =IF(Screening!G5="","",Screening!G5*ScenarioControls!$B$5) | K5: =IF(J5="","",InputData!$B$19+J5) | L5: =IF(K5="","",InputData!$B$18*K5/100)
A6: =Screening!A6 -> Immiscible Gas Flood | B6: =Screening!E6 -> FAIL (critical) | C6: =Screening!F6 -> Not suitable | D6: =IF(Screening!G6="","",Screening!G6*ScenarioControls!$B$3) | E6: =IF(D6="","",InputData!$B$19+D6) | F6: =IF(E6="","",InputData!$B$18*E6/100) | G6: =IF(Screening!G6="","",Screening!G6*ScenarioControls!$B$4) | H6: =IF(G6="","",InputData!$B$19+G6) | I6: =IF(H6="","",InputData!$B$18*H6/100) | J6: =IF(Screening!G6="","",Screening!G6*ScenarioControls!$B$5) | K6: =IF(J6="","",InputData!$B$19+J6) | L6: =IF(K6="","",InputData!$B$18*K6/100)
A7: =Screening!A7 -> Immiscible Gas WAG | B7: =Screening!E7 -> FAIL (critical) | C7: =Screening!F7 -> Not suitable | D7: =IF(Screening!G7="","",Screening!G7*ScenarioControls!$B$3) | E7: =IF(D7="","",InputData!$B$19+D7) | F7: =IF(E7="","",InputData!$B$18*E7/100) | G7: =IF(Screening!G7="","",Screening!G7*ScenarioControls!$B$4) | H7: =IF(G7="","",InputData!$B$19+G7) | I7: =IF(H7="","",InputData!$B$18*H7/100) | J7: =IF(Screening!G7="","",Screening!G7*ScenarioControls!$B$5) | K7: =IF(J7="","",InputData!$B$19+J7) | L7: =IF(K7="","",InputData!$B$18*K7/100)
A8: =Screening!A8 -> Polymer (HPAM) | B8: =Screening!E8 -> FAIL (critical) | C8: =Screening!F8 -> Not suitable | D8: =IF(Screening!G8="","",Screening!G8*ScenarioControls!$B$3) | E8: =IF(D8="","",InputData!$B$19+D8) | F8: =IF(E8="","",InputData!$B$18*E8/100) | G8: =IF(Screening!G8="","",Screening!G8*ScenarioControls!$B$4) | H8: =IF(G8="","",InputData!$B$19+G8) | I8: =IF(H8="","",InputData!$B$18*H8/100) | J8: =IF(Screening!G8="","",Screening!G8*ScenarioControls!$B$5) | K8: =IF(J8="","",InputData!$B$19+J8) | L8: =IF(K8="","",InputData!$B$18*K8/100)
A9: =Screening!A9 -> Polymer (ATBS) | B9: =Screening!E9 -> FAIL (critical) | C9: =Screening!F9 -> Not suitable | D9: =IF(Screening!G9="","",Screening!G9*ScenarioControls!$B$3) | E9: =IF(D9="","",InputData!$B$19+D9) | F9: =IF(E9="","",InputData!$B$18*E9/100) | G9: =IF(Screening!G9="","",Screening!G9*ScenarioControls!$B$4) | H9: =IF(G9="","",InputData!$B$19+G9) | I9: =IF(H9="","",InputData!$B$18*H9/100) | J9: =IF(Screening!G9="","",Screening!G9*ScenarioControls!$B$5) | K9: =IF(J9="","",InputData!$B$19+J9) | L9: =IF(K9="","",InputData!$B$18*K9/100)
A10: =Screening!A10 -> SP | B10: =Screening!E10 -> FAIL (critical) | C10: =Screening!F10 -> Not suitable | D10: =IF(Screening!G10="","",Screening!G10*ScenarioControls!$B$3) | E10: =IF(D10="","",InputData!$B$19+D10) | F10: =IF(E10="","",InputData!$B$18*E10/100) | G10: =IF(Screening!G10="","",Screening!G10*ScenarioControls!$B$4) | H10: =IF(G10="","",InputData!$B$19+G10) | I10: =IF(H10="","",InputData!$B$18*H10/100) | J10: =IF(Screening!G10="","",Screening!G10*ScenarioControls!$B$5) | K10: =IF(J10="","",InputData!$B$19+J10) | L10: =IF(K10="","",InputData!$B$18*K10/100)
A11: =Screening!A11 -> ASP | B11: =Screening!E11 -> FAIL (critical) | C11: =Screening!F11 -> Not suitable | D11: =IF(Screening!G11="","",Screening!G11*ScenarioControls!$B$3) | E11: =IF(D11="","",InputData!$B$19+D11) | F11: =IF(E11="","",InputData!$B$18*E11/100) | G11: =IF(Screening!G11="","",Screening!G11*ScenarioControls!$B$4) | H11: =IF(G11="","",InputData!$B$19+G11) | I11: =IF(H11="","",InputData!$B$18*H11/100) | J11: =IF(Screening!G11="","",Screening!G11*ScenarioControls!$B$5) | K11: =IF(J11="","",InputData!$B$19+J11) | L11: =IF(K11="","",InputData!$B$18*K11/100)
A12: =Screening!A12 -> CSS | B12: =Screening!E12 -> FAIL (critical) | C12: =Screening!F12 -> Not suitable | D12: =IF(Screening!G12="","",Screening!G12*ScenarioControls!$B$3) | E12: =IF(D12="","",InputData!$B$19+D12) | F12: =IF(E12="","",InputData!$B$18*E12/100) | G12: =IF(Screening!G12="","",Screening!G12*ScenarioControls!$B$4) | H12: =IF(G12="","",InputData!$B$19+G12) | I12: =IF(H12="","",InputData!$B$18*H12/100) | J12: =IF(Screening!G12="","",Screening!G12*ScenarioControls!$B$5) | K12: =IF(J12="","",InputData!$B$19+J12) | L12: =IF(K12="","",InputData!$B$18*K12/100)
A13: =Screening!A13 -> Steam Flood | B13: =Screening!E13 -> FAIL (critical) | C13: =Screening!F13 -> Not suitable | D13: =IF(Screening!G13="","",Screening!G13*ScenarioControls!$B$3) | E13: =IF(D13="","",InputData!$B$19+D13) | F13: =IF(E13="","",InputData!$B$18*E13/100) | G13: =IF(Screening!G13="","",Screening!G13*ScenarioControls!$B$4) | H13: =IF(G13="","",InputData!$B$19+G13) | I13: =IF(H13="","",InputData!$B$18*H13/100) | J13: =IF(Screening!G13="","",Screening!G13*ScenarioControls!$B$5) | K13: =IF(J13="","",InputData!$B$19+J13) | L13: =IF(K13="","",InputData!$B$18*K13/100)
A14: =Screening!A14 -> ISC | B14: =Screening!E14 -> FAIL (critical) | C14: =Screening!F14 -> Not suitable | D14: =IF(Screening!G14="","",Screening!G14*ScenarioControls!$B$3) | E14: =IF(D14="","",InputData!$B$19+D14) | F14: =IF(E14="","",InputData!$B$18*E14/100) | G14: =IF(Screening!G14="","",Screening!G14*ScenarioControls!$B$4) | H14: =IF(G14="","",InputData!$B$19+G14) | I14: =IF(H14="","",InputData!$B$18*H14/100) | J14: =IF(Screening!G14="","",Screening!G14*ScenarioControls!$B$5) | K14: =IF(J14="","",InputData!$B$19+J14) | L14: =IF(K14="","",InputData!$B$18*K14/100)

Sheet Summary
A1: EOR Screening Summary
A3: Top Recommended EOR Method (by score) | B3: =Ranking!B2 -> CO2 Miscible Flood
A4: Score (%) | B4: =Ranking!C2 -> 0
A5: Status | B5: =Ranking!D2 -> FAIL (critical)
A6: Suitability | B6: =Ranking!E2 -> Not suitable
A8: Main Technical References
A9: R1 Taber et al. 1997 – EOR Screening Criteria Revisited
A10: R2 Arvis & Min 2025 – Updated screening criteria for EOR methods
A11: R3/R4 Recent CO2 and CO2-WAG screening, MMP, and waterflood-history work
A12: R5/R6/R7 Polymer and SP updates for HTHS/offshore/carbonate contexts
A14: Recovery Factor & EUR Logic
A15: ΔRF_EOR = Score × Max Incremental RF × Drive Mechanism Multiplier × Field Maturity Factor
A16: P10/P50/P90 ranges scale incremental RF only, not base RF.
A18: Top Option Scenario Range
A19: P90 Final RF (%) | B19: =INDEX(RF_EUR_Ranges!$E$2:$E$12,MATCH(B3,RF_EUR_Ranges!$A$2:$A$12,0))
A20: P50 Final RF (%) | B20: =INDEX(RF_EUR_Ranges!$H$2:$H$12,MATCH(B3,RF_EUR_Ranges!$A$2:$A$12,0))
A21: P10 Final RF (%) | B21: =INDEX(RF_EUR_Ranges!$K$2:$K$12,MATCH(B3,RF_EUR_Ranges!$A$2:$A$12,0))
A22: P90 EUR (MMstb) | B22: =INDEX(RF_EUR_Ranges!$F$2:$F$12,MATCH(B3,RF_EUR_Ranges!$A$2:$A$12,0))
A23: P50 EUR (MMstb) | B23: =INDEX(RF_EUR_Ranges!$I$2:$I$12,MATCH(B3,RF_EUR_Ranges!$A$2:$A$12,0))
A24: P10 EUR (MMstb) | B24: =INDEX(RF_EUR_Ranges!$L$2:$L$12,MATCH(B3,RF_EUR_Ranges!$A$2:$A$12,0))
B26: =INDEX(RF_EUR_Ranges!$E$2:$E$14,MATCH(B3,RF_EUR_Ranges!$A$2:$A$14,0))
B27: =INDEX(RF_EUR_Ranges!$H$2:$H$14,MATCH(B3,RF_EUR_Ranges!$A$2:$A$14,0))
B28: =INDEX(RF_EUR_Ranges!$K$2:$K$14,MATCH(B3,RF_EUR_Ranges!$A$2:$A$14,0))
B30: =INDEX(RF_EUR_Ranges!$F$2:$F$14,MATCH(B3,RF_EUR_Ranges!$A$2:$A$14,0))
B31: =INDEX(RF_EUR_Ranges!$I$2:$I$14,MATCH(B3,RF_EUR_Ranges!$A$2:$A$14,0))
B32: =INDEX(RF_EUR_Ranges!$L$2:$L$14,MATCH(B3,RF_EUR_Ranges!$A$2:$A$14,0))

Sheet ScenarioControls
A1: Scenario Controls for RF/EUR Ranges
A2: Parameter | B2: Value | C2: Note
A3: P90 incremental RF factor | B3: 0.8 | C3: Conservative case applied to incremental RF only
A4: P50 incremental RF factor | B4: 1 | C4: Base case = current calculated incremental RF
A5: P10 incremental RF factor | B5: 1.2 | C5: Upside case applied to incremental RF only
A6: Important note | C6: These are screening-level scenario factors, not full probabilistic reservoir simulation outputs.

Sheet Criteria
A1: EOR Type | B1: Parameter | C1: 2026 Screening Condition | D1: Fail When | E1: Critical? | F1: Ref ID(s) | G1: Short Reference / Note | H1: Reference URL
A2: CO2 Miscible Flood | B2: CO2 Availability | C2: Yes | D2: CO2 unavailable | E2: Yes | F2: R3;R4 | G2: CO2-specific source availability is critical; not interchangeable with HC gas. | H2: https://www.sciencedirect.com/science/article/pii/S2405656125000161
A3: CO2 Miscible Flood | B3: MMP Satisfied? | C3: Yes | D3: Pressure below MMP | E3: Yes | F3: R3;R4 | G3: CO2 miscibility requires reservoir pressure at/above MMP. | H3: https://www.mdpi.com/2073-4441/17/5/651
A4: CO2 Miscible Flood | B4: API / Viscosity / Depth | C4: >=25° API, <=10 cP, >=2500 ft | D4: Outside range | E4: Yes | F4: R1;R2 | G4: Updated miscible gas screening range. | H4: https://www.nature.com/articles/s41598-025-21696-x
A5: CO2 WAG | B5: WAG Facilities | C5: Water + gas injection facilities available | D5: Facilities unavailable | E5: Yes | F5: R4 | G5: WAG requires both injection systems and cycle management. | H5: https://www.mdpi.com/2073-4441/17/5/651
A6: CO2 WAG | B6: Gravity Override Risk | C6: Low/Medium preferred | D6: High = conditional | E6: Conditional | F6: R4 | G6: WAG can improve sweep but override/channeling still penalizes score. | H6: https://www.mdpi.com/2073-4441/17/5/651
A7: HC Gas Miscible Flood | B7: HC Gas Source | C7: External HC gas OR high GOR with reinjection potential | D7: No gas source and no reinjection potential | E7: Yes/Conditional | F7: R10;R11 | G7: High GOR + reinjection can be conditional source for HC gas recycling. | H7: https://www.onepetro.org/
A8: HC Gas Miscible Flood | B8: MMP Satisfied? | C8: Yes | D8: Pressure below MMP | E8: Yes | F8: R10 | G8: HC miscible gas needs MMP check separate from CO2. | H8: https://www.onepetro.org/
A9: HC Gas WAG | B9: HC Gas Source + WAG Facilities | C9: HC gas source + water/gas injection facilities | D9: Source/facilities unavailable | E9: Yes/Conditional | F9: R10;R11 | G9: HC WAG combines gas recycling/source with WAG facilities. | H9: https://www.onepetro.org/
A10: Immiscible Gas Flood | B10: Gas Source | C10: Gas available OR high GOR with reinjection potential | D10: No gas source | E10: Yes/Conditional | F10: R1;R11 | G10: Immiscible gas can be supported by recycled associated gas if feasible. | H10: https://www.onepetro.org/
A11: Immiscible Gas WAG | B11: Gas Source + WAG Facilities | C11: Gas source + water/gas injection facilities | D11: Source/facilities unavailable | E11: Yes/Conditional | F11: R4;R11 | G11: WAG improves sweep versus continuous gas but requires water and gas injectivity. | H11: https://www.mdpi.com/2073-4441/17/5/651
A12: Polymer (HPAM) | B12: Temperature / Salinity / Hardness | C12: <=70°C, <=70k ppm TDS, <=500 ppm hardness | D12: Outside range | E12: Yes | F12: R1;R5 | G12: Conventional HPAM limit retained. | H12: https://www.nature.com/articles/s41598-023-44896-9
... A22: GOR Category from Numeric | B22: Optional helper | C22: Tool default: >=1000 scf/STB High; 300–999 Moderate; <300 Low | D22: Blank uses manual category input | E22: Optional | F22: Tool assumption; R10 | G22: This is a screening proxy, not a universal reservoir standard; user may override via Produced GOR Category. | H22: https://www.mdpi.com/1996-1073/18/15/4182

Sheet References_2026
A1: Ref ID | B1: Reference | C1: Year | D1: Key use in this workbook | E1: URL
A2: R1 | B2: Taber, Martin & Seright, EOR screening criteria revisited (Parts 1–2), SPE Reservoir Engineering. | C2: 1997 | D2: Legacy baseline criteria for miscible gas, chemical and thermal EOR. | E2: https://doi.org/10.2118/35385-PA
A3: R2 | B3: Arvis & Min, Updated screening criteria for enhanced oil recovery methods, Scientific Reports. | C3: 2025 | D3: Updated screening/scoring workflow and score-based exclusion. | E3: https://www.nature.com/articles/s41598-025-21696-x
A4: R3 | B4: Recent CO2-EOR / CCUS screening reviews. | C4: 2024–2025 | D4: CO2 source, MMP, injectivity, containment, WAG screening factors. | E4: https://www.sciencedirect.com/science/article/pii/S2405656125000161
A5: R4 | B5: Recent CO2 WAG screening and optimization studies. | C5: 2025 | D5: Waterflood history, residual oil contact, WAG suitability and injectivity criteria. | E5: https://www.mdpi.com/2073-4441/17/5/651
A6: R5 | B6: Zeynalli et al., Review of viscoelastic polymer flooding in sandstone and carbonate rocks, Scientific Reports. | C6: 2023 | D6: ATBS/NVP high-temperature/high-salinity polymers, oxygen sensitivity, injectivity. | E6: https://www.nature.com/articles/s41598-023-44896-9
A7: R6 | B7: Recent offshore carbonate surfactant-polymer formulation studies. | C7: 2024 | D7: SP in high-temperature/offshore carbonate reservoirs; adsorption and handling risks. | E7: https://www.frontiersin.org/journals/chemistry/articles/10.3389/fchem.2024.1408115/full
A8: R7 | B8: Surfactant-polymer flooding in carbonates under harsh conditions review. | C8: 2023 | D8: SP feasibility in high salinity/high temperature carbonate reservoirs. | E8: https://www.sciencedirect.com/science/article/pii/S0920410522010956
A9: R8 | B9: Xu et al., Review of steam flooding and applications. | C9: 2023 | D9: Thermal EOR remains suited to heavy/viscous oil, shallow depths, high permeability. | E9: https://www.frontiersin.org/journals/earth-science/articles/10.3389/feart.2023.1268103/full
A10: R9 | B10: Recent anti-salt surfactant/polymer screening in low-permeability reservoirs. | C10: 2026 | D10: AM/AMPS/AA polymer and SP evidence in lower-perm reservoirs with retention/shear checks. | E10: https://www.mdpi.com/2227-9717/14/3/408
A11: R10 | B11: Soltanbekova et al., Potential of Gas-Enhanced Oil Recovery (EOR) Methods: Experimental and Simulation Analysis, Energies. | C11: 2025 | D11: Gas-EOR methods include hydrocarbon gases, nitrogen, flue gas, WAG and CO2 flooding; supports split gas modules. | E11: https://www.mdpi.com/1996-1073/18/15/4182
A12: R11 | B12: U.S. Department of Energy, CCUS Chapter 8 – CO2 Enhanced Oil Recovery. | C12: 2021 | D12: CO2-EOR commonly uses WAG and produced CO2 is recycled/reinjected; supports separation of CO2-specific workflow. | E12: https://www.energy.gov/sites/default/files/2022-10/CCUS-Chap_8-030521.pdf
... A14: R13 | B14: USGS Fact Sheet: Field growth and role of EOR. | C14: 2000 | D14: CO2 gas injection and miscible/immiscible hydrocarbon gas injection are distinct EOR techniques; supports separate CO2 vs HC gas rows. | E14: https://pubs.usgs.gov/fs/fs-0115-00/fs-0115-00po.pdf

Sheet Lists
A1: RockType | B1: Heterogeneity | C1: YesNo | D1: DriveMechanism | E1: FieldMaturity | F1: MobilityRatio | G1: RiskLevel | H1: Injectivity | I1: WAGRatio | J1: GORCategory | K1: YesNoUnknown | L1: GasSourceStatus
A2: Sandstone | B2: Low | C2: Yes | D2: Solution Gas Drive | E2: Early | F2: Favorable | G2: Low | H2: Good | I2: 1:1 | J2: Low | K2: Yes | L2: Available
A3: Carbonate | B3: Moderate | C3: No | D3: Weak Water Drive | E3: Mid | F3: Neutral | G3: Medium | H3: Fair | I3: 2:1 | J3: Moderate | K3: No | L3: Conditional
B4: High | D4: Moderate Water Drive | E4: Late | F4: Unfavorable | G4: High | H4: Poor | I4: 1:2 | J4: High | K4: Unknown | L4: Unavailable
D5: Strong Water Drive | I5: Custom | J5: Unknown
D6: Gas Cap Expansion
D7: Combination Drive
D8: Natural Fracture
D9: Others

Sheet EOR_Data Gathering
A1: DATA GATHERING
A3: Section | B3: Field | C3: Type | D3: Value | E3: Units/Notes | F3: Guidance
A4: Overview | B4: Project Name | C4: text | D4: Garraf EOR Screening | F4: Project identifier
B5: Field | C5: text | D5: Garraf
B6: Reservoir / Zone | C6: text | D6: Mishrif
B7: Current Recovery Mechanism | C7: list:Primary; Waterflood; Gasflood; Other | D7: Waterflood | F7: Select one
B8: Current RF | D8: 0.2 | E8: % | F8: at Techlife
B9: EOR Methods Under Consideration | C9: list:CO2 miscible; HC gas miscible; Polymer; ASP; Surfactant; Thermal; WAG; HnP; Other | D9: Polymer, ASP, Surfactant | F9: Choose most likely method at this stage
B10: Data Cutoff Date | C10: date | D10: 46022 | F10: YYYY-MM-DD
B11: Report Source / Reference | C11: text | F11: Link or document ID
A12: Reservoir & Rock | B12: Depth TVDSS | C12: number | D12: 2300 | E12: m
B13: Net Pay | C13: number | D13: 38 | E13: m
B14: Gross Thickness | C14: number | D14: 38 | E14: m
B15: Area | C15: number | E15: km^2
B16: Porosity, phi | C16: number | D16: 0.24 | F16: fraction (0-1)
B17: Permeability, k | C17: number | D17: 30 | E17: mD
B18: NTG | C18: number | D18: 1 | F18: fraction (0-1)
B19: Kv/Kh | C19: number | D19: 0.7 | E19: ratio
B20: Initial Swi | C20: number | F20: fraction (0-1)
B21: Sor | C21: number | F21: fraction (0-1)
B22: Wettability Index (Amott/USBM) | C22: text | F22: state index & method
B23: Capillary Pressure Curves Available? | C23: list:Yes; No | F23: Yes/No
B24: Rock Type / Lithology | C24: list:Sandstone; Carbonate; Mixed; Shale; Other | D24: Carbonate
B25: Fracturing (Natural/Induced) | C25: list:None; Natural; Induced; Both | D25: Natural
B26: Temperature | C26: number | D26: 74 | E26: °C
B27: Initial Reservoir Pressure | C27: number | D27: 3900 | E27: psi
B28: Current Reservoir Pressure | C28: number | D28: 3100 | E28: psi
B29: Bubble Point Pressure, Pb | C29: number | D29: 2646 | E29: psi
A30: Fluids (PVT & Water) | B30: Fluid type | C30: text | D30: Black Oil (Medium) | F30: Volatile Oil, Dry Gas, Wet Gas, Gas‑Condensate, Black Oil (Light/Medium Oil), Heavy Oil, Extra‑Heavy Oil / Bitumen
B31: GOR | C31: number | D31: 574 | E31: scf/STB
B32: Oil Density @ 20°C | C32: number | E32: g/cc
B33: Oil Density @ Pb | C33: number | D33: 0.75 | E33: g/cc
B34: API Gravity | C34: number | D34: 25 | E34: deg API
B35: Oil Viscosity @ reservoir | C35: number | D35: 2.2 | E35: cP
B36: Oil Viscosity @ Pb | C36: number | D36: 1.78 | E36: cP
B37: MMP (if available)
B38: Solution Gas Composition | C38: Number and text | D38: 98.7 mol%:C1-C7+ 0.54 mol%: C02 0.75 mol%:N2 | E38: mol% | F38: mol% (C1-C7+, CO2, N2, H2S)
B39: Stock Tank Oil Composition (SARA) | C39: Number and text | D39: 44.2 wt%: Saturates 43.5 wt%: Aromatics 11.7 wt%: Resins 0.6 wt%: Asphalthenes | E39: wt% | F39: %wt Saturates/Aromatics/Resins/Asphaltenes | M39: Yes
B40: Formation Water Salinity | C40: number | D40: 177000 | E40: ppm | F40: ppm TDS | M40: No
B41: Formation Water Composition | C41: Number and text | E41: ppm | F41: ppm cation and Anions (Na, Ca, Mg, Cl, SO4, HCO3 etc) | J41: Issue | K41: Risk Level | L41: Reason
...

Sheet Coreflood
